<?xml version="1.0" ?>
<!-- This URDF was automatically created by SolidWorks to URDF Exporter! Originally created by Stephen Brawner (brawner@gmail.com) 
     Commit Version: 1.6.0-4-g7f85cfe  Build Version: 1.6.7995.38578
     For more information, please see http://wiki.ros.org/sw_urdf_exporter -->
<robot
  name="mobilerobot" xmlns:xacro="http://ros.org/wiki/xacro">

  <xacro:macro name="base_color">
    <visual>
    <material>
        <ambient>0.8 0.558823529411765 0.1 1</ambient>
        <diffuse>0.8 0.558823529411765 0.1 1</diffuse>
        <specular>0.1 0.1 0.1 1</specular>
        <emissive>0 0 0 0</emissive>
    </material>
    </visual>
  </xacro:macro>

  <xacro:macro name="lidar_color">
    <visual>
    <material>
        <ambient>0.8 1 0.5 1</ambient>
        <diffuse>0.8 0.558823529411765 0.1 1</diffuse>
        <specular>0.1 0.1 0.1 1</specular>
        <emissive>0 0 0 0</emissive>
    </material>
    </visual>
  </xacro:macro>

  <xacro:macro name="fr_steering_color">
    <visual>
    <material>
        <ambient>0.8 0.558823529411765 0.1 1</ambient>
        <diffuse>0.8 0.558823529411765 0.1 1</diffuse>
        <specular>0.1 0.1 0.1 1</specular>
        <emissive>0 0 0 0</emissive>
    </material>
    </visual>
  </xacro:macro>

  <xacro:macro name="fl_steering_color">
    <visual>
    <material>
        <ambient>0.8 0.558823529411765 0.1 1</ambient>
        <diffuse>0.8 0.558823529411765 0.1 1</diffuse>
        <specular>0.1 0.1 0.1 1</specular>
        <emissive>0 0 0 0</emissive>
    </material>
    </visual>
  </xacro:macro>

  <xacro:macro name="fr_wheel_color">
    <visual>
    <material>
        <ambient>0.8 0.558823529411765 0.1 1</ambient>
        <diffuse>0.5 1 1 1</diffuse>
        <specular>0.1 0.1 0.1 1</specular>
        <emissive>0 0 0 0</emissive>
    </material>
    </visual>
  </xacro:macro>

  <xacro:macro name="fl_wheel_color">
    <visual>
    <material>
        <ambient>0.8 0.558823529411765 0.1 1</ambient>
        <diffuse>0.5 1 1 1</diffuse>
        <specular>0.1 0.1 0.1 1</specular>
        <emissive>0 0 0 0</emissive>
    </material>
    </visual>
  </xacro:macro>

  <xacro:macro name="rear_wheel_color">
    <visual>
    <material>
        <ambient>0.5 1 1 1</ambient>
        <diffuse>0.8 0.558823529411765 0.1 1</diffuse>
        <specular>0.5 1 1 1</specular>
        <emissive>0 0 0 0</emissive>
    </material>
    </visual>
  </xacro:macro>

  <link
    name="base_link">
    <inertial>
      <origin
        xyz="-0.00560849394349254 0.138416441373908 0.19747867501079"
        rpy="0 0 0" />
      <mass
        value="34.0402726835256" />
      <inertia
        ixx="2.24728990824315"
        ixy="0.00404555641679376"
        ixz="-0.00113851011413642"
        iyy="0.846977465952566"
        iyz="0.156024975233451"
        izz="2.92868788674484" />
    </inertial>
    <visual>
      <origin
        xyz="0 0 0"
        rpy="0 0 0" />
      <geometry>
        <mesh
          filename="package://mobilerobot/meshes/base_link.STL" />
      </geometry>
      <material
        name="">
        <color
          rgba="0.792156862745098 0.819607843137255 0.933333333333333 1" />
      </material>
    </visual>
    <collision>
      <origin
        xyz="0 0 0"
        rpy="0 0 0" />
      <geometry>
        <mesh
          filename="package://mobilerobot/meshes/base_link.STL" />
      </geometry>
    </collision>
  </link>
  <link
    name="lidar_link">
    <inertial>
      <origin
        xyz="2.60208521396521E-18 -0.130418177424952 0"
        rpy="0 0 0" />
      <mass
        value="8.11052962365955" />
      <inertia
        ixx="0.0664312003338709"
        ixy="1.39906896132096E-19"
        ixz="-9.74699727049626E-19"
        iyy="0.0455559977058692"
        iyz="6.60658147708487E-18"
        izz="0.0664312003338709" />
    </inertial>
    <visual>
      <origin
        xyz="0 0 0"
        rpy="0 0 0" />
      <geometry>
        <mesh
          filename="package://mobilerobot/meshes/lidar_link.STL" />
      </geometry>
      <material
        name="">
        <color
          rgba="0.792156862745098 0.819607843137255 0.933333333333333 1" />
      </material>
    </visual>
    <collision>
      <origin
        xyz="0 0 0"
        rpy="0 0 0" />
      <geometry>
        <mesh
          filename="package://mobilerobot/meshes/lidar_link.STL" />
      </geometry>
    </collision>
  </link>
  <joint
    name="lidar_joint"
    type="fixed">
    <origin
      xyz="-0.0052189 0.23146 0.48578"
      rpy="1.5708 0 0" />
    <parent
      link="base_link" />
    <child
      link="lidar_link" />
    <axis
      xyz="0 0 0" />
  </joint>
  <link
    name="fr_steering_link">
    <inertial>
      <origin
        xyz="-0.0295443420976313 -0.0453856579023687 5.55111512312578E-17"
        rpy="0 0 0" />
      <mass
        value="0.0414034399621029" />
      <inertia
        ixx="3.33947062706257E-05"
        ixy="-7.48507068731089E-06"
        ixz="-4.01997670169752E-22"
        iyy="1.31963056728814E-05"
        iyz="1.19852618177322E-20"
        izz="3.54762303335987E-05" />
    </inertial>
    <visual>
      <origin
        xyz="0 0 0"
        rpy="0 0 0" />
      <geometry>
        <mesh
          filename="package://mobilerobot/meshes/fr_steering_link.STL" />
      </geometry>
      <material
        name="">
        <color
          rgba="0.792156862745098 0.819607843137255 0.933333333333333 1" />
      </material>
    </visual>
    <collision>
      <origin
        xyz="0 0 0"
        rpy="0 0 0" />
      <geometry>
        <mesh
          filename="package://mobilerobot/meshes/fr_steering_link.STL" />
      </geometry>
    </collision>
  </link>
  <joint
    name="fr_steering_joint"
    type="revolute">
    <origin
      xyz="-0.13222 -0.2671 0.19622"
      rpy="1.5708 0 0" />
    <parent
      link="base_link" />
    <child
      link="fr_steering_link" />
    <axis
      xyz="0 -1 0" />
    <limit
      lower="-3.14"
      upper="1000"
      effort="5"
      velocity="3.14" />
  </joint>
  <link
    name="fr_wheel_link">
    <inertial>
      <origin
        xyz="-0.0285358747785263 1.2490009027033E-16 1.66533453693773E-16"
        rpy="0 0 0" />
      <mass
        value="1.23678767738643" />
      <inertia
        ixx="0.0085544168067291"
        ixy="2.32465685020744E-18"
        ixz="1.19228656050549E-18"
        iyy="0.00479938090223406"
        iyz="-4.88711876828246E-19"
        izz="0.00479938090223406" />
    </inertial>
    <visual>
      <origin
        xyz="0 0 0"
        rpy="0 0 0" />
      <geometry>
        <mesh
          filename="package://mobilerobot/meshes/fr_wheel_link.STL" />
      </geometry>
      <material
        name="">
        <color
          rgba="0.792156862745098 0.819607843137255 0.933333333333333 1" />
      </material>
    </visual>
    <collision>
      <origin
        xyz="0 0 0"
        rpy="0 0 0" />
      <geometry>
        <mesh
          filename="package://mobilerobot/meshes/fr_wheel_link.STL" />
      </geometry>
    </collision>
  </link>
  <joint
    name="fr_wheel_joint"
    type="continuous">
    <origin
      xyz="-0.061087 -0.09271 0"
      rpy="0 0 0" />
    <parent
      link="fr_steering_link" />
    <child
      link="fr_wheel_link" />
    <axis
      xyz="-1 0 0" />
  </joint>
  <link
    name="fl_steering_link">
    <inertial>
      <origin
        xyz="0.0295443420976313 -0.0453856579023686 4.9960036108132E-16"
        rpy="0 0 0" />
      <mass
        value="0.0414034399621028" />
      <inertia
        ixx="3.33947062706257E-05"
        ixy="7.48507068731088E-06"
        ixz="-5.70179001236255E-21"
        iyy="1.31963056728814E-05"
        iyz="-6.13977457084149E-21"
        izz="3.54762303335986E-05" />
    </inertial>
    <visual>
      <origin
        xyz="0 0 0"
        rpy="0 0 0" />
      <geometry>
        <mesh
          filename="package://mobilerobot/meshes/fl_steering_link.STL" />
      </geometry>
      <material
        name="">
        <color
          rgba="0.792156862745098 0.819607843137255 0.933333333333333 1" />
      </material>
    </visual>
    <collision>
      <origin
        xyz="0 0 0"
        rpy="0 0 0" />
      <geometry>
        <mesh
          filename="package://mobilerobot/meshes/fl_steering_link.STL" />
      </geometry>
    </collision>
  </link>
  <joint
    name="fl_steering_joint"
    type="revolute">
    <origin
      xyz="0.12178 -0.2671 0.19622"
      rpy="1.5708 0 0" />
    <parent
      link="base_link" />
    <child
      link="fl_steering_link" />
    <axis
      xyz="0 -1 0" />
    <limit
      lower="-3.14"
      upper="1000"
      effort="5"
      velocity="3.14" />
  </joint>
  <link
    name="fl_wheel_link">
    <inertial>
      <origin
        xyz="0.0285358747785263 -5.55111512312578E-17 -5.55111512312578E-16"
        rpy="0 0 0" />
      <mass
        value="1.23678767738643" />
      <inertia
        ixx="0.0085544168067291"
        ixy="3.3321210554159E-18"
        ixz="-1.20301187144444E-18"
        iyy="0.00479938090223407"
        iyz="2.87775165754918E-18"
        izz="0.00479938090223407" />
    </inertial>
    <visual>
      <origin
        xyz="0 0 0"
        rpy="0 0 0" />
      <geometry>
        <mesh
          filename="package://mobilerobot/meshes/fl_wheel_link.STL" />
      </geometry>
      <material
        name="">
        <color
          rgba="0.792156862745098 0.819607843137255 0.933333333333333 1" />
      </material>
    </visual>
    <collision>
      <origin
        xyz="0 0 0"
        rpy="0 0 0" />
      <geometry>
        <mesh
          filename="package://mobilerobot/meshes/fl_wheel_link.STL" />
      </geometry>
    </collision>
  </link>
  <joint
    name="fl_wheel_joint"
    type="continuous">
    <origin
      xyz="0.0610869999999999 -0.0927099999999999 0"
      rpy="0 0 0" />
    <parent
      link="fl_steering_link" />
    <child
      link="fl_wheel_link" />
    <axis
      xyz="1 0 0" />
  </joint>
  <link
    name="rear_wheel_link">
    <inertial>
      <origin
        xyz="3.49150535141826E-08 6.93889390390723E-17 2.77555756156289E-16"
        rpy="0 0 0" />
      <mass
        value="2.6258071673135" />
      <inertia
        ixx="0.0171205868769986"
        ixy="-4.33216455753514E-21"
        ixz="-4.40036526604151E-17"
        iyy="0.128033261320504"
        iyz="6.59123361476402E-18"
        izz="0.128033261320504" />
    </inertial>
    <visual>
      <origin
        xyz="0 0 0"
        rpy="0 0 0" />
      <geometry>
        <mesh
          filename="package://mobilerobot/meshes/rear_wheel_link.STL" />
      </geometry>
      <material
        name="">
        <color
          rgba="0.792156862745098 0.819607843137255 0.933333333333333 1" />
      </material>
    </visual>
    <collision>
      <origin
        xyz="0 0 0"
        rpy="0 0 0" />
      <geometry>
        <mesh
          filename="package://mobilerobot/meshes/rear_wheel_link.STL" />
      </geometry>
    </collision>
  </link>
  <joint
    name="rear_wheel_joint"
    type="continuous">
    <origin
      xyz="-0.0052189 0.23146 0.1016"
      rpy="1.5708 0 -3.1416" />
    <parent
      link="base_link" />
    <child
      link="rear_wheel_link" />
    <axis
      xyz="-1 0 0" />
  </joint>

<gazebo reference="base_link">
    <xacro:base_color />
</gazebo>

<gazebo reference="lidar_link">
    <xacro:lidar_color />
</gazebo>

<gazebo reference="fr_steering_link">
    <xacro:fr_steering_color />
</gazebo>

<gazebo reference="fl_steering_link">
    <xacro:fl_steering_color />
</gazebo>

<gazebo reference="fr_wheel_link">
    <xacro:fr_wheel_color />
</gazebo>

<gazebo reference="fl_wheel_link">
    <xacro:fl_wheel_color />
</gazebo>

<gazebo reference="rear_wheel_link">
    <xacro:rear_wheel_color />
</gazebo>

 <ros2_control name="GazeboSystem" type="system">
 <hardware>
     <plugin>gazebo_ros2_control/GazeboSystem</plugin>
 </hardware>

 # Velocity Controllers

 <joint name="rear_wheel_joint">
     <command_interface name="velocity">
         <param name="min">-1000.0</param>
         <param name="max">1000.0</param>
     </command_interface>
     <state_interface name="position"/>
     <state_interface name="velocity"/>
 </joint>

# Position Controller
 <joint name="fl_steering_joint">
     <command_interface name="position">
         <param name="min">-3.14</param>
         <param name="max">3.14</param>
     </command_interface>
     <state_interface name="position"/>
     <state_interface name="velocity"/>
 </joint>

  <joint name="fl_steering_joint">
     <command_interface name="position">
         <param name="min">-3.14</param>
         <param name="max">3.14</param>
     </command_interface>
     <state_interface name="position"/>
     <state_interface name="velocity"/>
 </joint>

 </ros2_control>

 <gazebo>
    <plugin filename="libgazebo_ros2_control.so" name="gazebo_ros2_control">
        <parameters>$(find mobilerobot)/config/control.yaml</parameters>
    </plugin>
</gazebo>

</robot>